{"recv_ts_ns": 1776490453460692000, "raw": "{\"type\":\"subscribed\",\"id\":1,\"msg\":{\"channel\":\"orderbook_delta\",\"sid\":1}}\n"}
{"recv_ts_ns": 1776490453460719000, "raw": "{\"type\":\"orderbook_snapshot\",\"sid\":1,\"seq\":1,\"msg\":{\"market_ticker\":\"KXBTC-26APR1817-B76125\",\"market_id\":\"fb95fe57-d4f2-4f3f-956c-f7011063d20f\",\"yes_dollars_fp\":[[\"0.0100\",\"5000.00\"],[\"0.0200\",\"205.00\"]],\"no_dollars_fp\":[[\"0.0100\",\"106.00\"],[\"0.0200\",\"150.00\"],[\"0.0300\",\"82.00\"],[\"0.0400\",\"14.00\"],[\"0.0500\",\"20.00\"],[\"0.0600\",\"196.00\"],[\"0.0800\",\"13.00\"],[\"0.0900\",\"2.00\"],[\"0.1100\",\"10.00\"],[\"0.1200\",\"3.00\"],[\"0.1400\",\"8.00\"],[\"0.1600\",\"4.00\"],[\"0.1700\",\"6.00\"],[\"0.2000\",\"8.00\"],[\"0.2400\",\"2.00\"],[\"0.3100\",\"2.00\"],[\"0.3600\",\"2.00\"],[\"0.7100\",\"1.00\"],[\"0.7600\",\"1.00\"],[\"0.8000\",\"250.00\"],[\"0.8100\",\"1.00\"],[\"0.8600\",\"1.00\"],[\"0.9300\",\"5130.00\"]]}}\n"}
{"recv_ts_ns": 1776490453460739000, "raw": "{\"type\":\"orderbook_snapshot\",\"sid\":1,\"seq\":2,\"msg\":{\"market_ticker\":\"KXBTC-26APR1817-B76375\",\"market_id\":\"dd3d87a3-a280-44b0-8c23-8fa091b5331e\",\"yes_dollars_fp\":[[\"0.0300\",\"5213.00\"]],\"no_dollars_fp\":[[\"0.0100\",\"68.00\"],[\"0.0200\",\"50.00\"],[\"0.0400\",\"14.00\"],[\"0.0500\",\"20.00\"],[\"0.0600\",\"1.00\"],[\"0.0800\",\"13.00\"],[\"0.0900\",\"2.00\"],[\"0.1100\",\"10.00\"],[\"0.1200\",\"3.00\"],[\"0.1400\",\"8.00\"],[\"0.1600\",\"4.00\"],[\"0.1700\",\"6.00\"],[\"0.2000\",\"8.00\"],[\"0.2400\",\"2.00\"],[\"0.3100\",\"2.00\"],[\"0.3600\",\"2.00\"],[\"0.7100\",\"1.00\"],[\"0.7600\",\"1.00\"],[\"0.8100\",\"1.00\"],[\"0.8600\",\"1.00\"],[\"0.9100\",\"5000.00\"],[\"0.9200\",\"174.00\"]]}}\n"}
{"recv_ts_ns": 1776490453460751000, "raw": "{\"type\":\"orderbook_snapshot\",\"sid\":1,\"seq\":3,\"msg\":{\"market_ticker\":\"KXBTC-26APR1817-B76625\",\"market_id\":\"0e7966ce-51c0-40fd-a4ba-37acacc26135\",\"yes_dollars_fp\":[[\"0.0400\",\"5000.00\"],[\"0.0500\",\"211.00\"]],\"no_dollars_fp\":[[\"0.0100\",\"6.00\"],[\"0.0200\",\"50.00\"],[\"0.0400\",\"14.00\"],[\"0.0500\",\"20.00\"],[\"0.0600\",\"1.00\"],[\"0.0800\",\"13.00\"],[\"0.0900\",\"2.00\"],[\"0.1100\",\"10.00\"],[\"0.1200\",\"3.00\"],[\"0.1400\",\"8.00\"],[\"0.1600\",\"4.00\"],[\"0.1700\",\"6.00\"],[\"0.2000\",\"8.00\"],[\"0.2400\",\"2.00\"],[\"0.3100\",\"2.00\"],[\"0.3600\",\"2.00\"],[\"0.7100\",\"1.00\"],[\"0.7600\",\"1.00\"],[\"0.8100\",\"1.00\"],[\"0.8800\",\"5000.00\"],[\"0.8900\",\"210.00\"],[\"0.9100\",\"1.00\"]]}}\n"}
{"recv_ts_ns": 1776490453460762000, "raw": "{\"type\":\"orderbook_snapshot\",\"sid\":1,\"seq\":4,\"msg\":{\"market_ticker\":\"KXBTC-26APR1817-B76875\",\"market_id\":\"40b92a88-8bde-4a7e-9d41-da979865ae04\",\"yes_dollars_fp\":[[\"0.1200\",\"5000.00\"]],\"no_dollars_fp\":[[\"0.0100\",\"206.00\"],[\"0.0200\",\"150.00\"],[\"0.0300\",\"137.00\"],[\"0.0400\",\"14.00\"],[\"0.0500\",\"20.00\"],[\"0.0600\",\"1.00\"],[\"0.0800\",\"13.00\"],[\"0.0900\",\"2.00\"],[\"0.1100\",\"10.00\"],[\"0.1200\",\"3.00\"],[\"0.1400\",\"8.00\"],[\"0.1600\",\"4.00\"],[\"0.1700\",\"6.00\"],[\"0.2000\",\"8.00\"],[\"0.2400\",\"2.00\"],[\"0.3100\",\"2.00\"],[\"0.3600\",\"2.00\"],[\"0.7100\",\"1.00\"],[\"0.7600\",\"1.00\"],[\"0.8100\",\"5000.00\"],[\"0.8200\",\"52.00\"]]}}\n"}
{"recv_ts_ns": 1776490453462061000, "raw": "{\"type\":\"orderbook_snapshot\",\"sid\":1,\"seq\":5,\"msg\":{\"market_ticker\":\"KXBTC-26APR1817-B77375\",\"market_id\":\"585395e9-aa6b-4085-931c-5c8399d3f5b8\",\"yes_dollars_fp\":[[\"0.1500\",\"5000.00\"]],\"no_dollars_fp\":[[\"0.0100\",\"206.00\"],[\"0.0200\",\"150.00\"],[\"0.0300\",\"137.00\"],[\"0.0400\",\"14.00\"],[\"0.0500\",\"20.00\"],[\"0.0600\",\"1.00\"],[\"0.0800\",\"13.00\"],[\"0.0900\",\"2.00\"],[\"0.1100\",\"10.00\"],[\"0.1200\",\"3.00\"],[\"0.1400\",\"8.00\"],[\"0.1600\",\"4.00\"],[\"0.1700\",\"6.00\"],[\"0.2000\",\"8.00\"],[\"0.2400\",\"2.00\"],[\"0.3100\",\"2.00\"],[\"0.3600\",\"140.96\"],[\"0.7100\",\"1.00\"],[\"0.7600\",\"1.00\"],[\"0.7700\",\"5005.00\"]]}}\n"}
{"recv_ts_ns": 1776490453462074000, "raw": "{\"type\":\"orderbook_snapshot\",\"sid\":1,\"seq\":6,\"msg\":{\"market_ticker\":\"KXBTC-26APR1817-B77625\",\"market_id\":\"1525682e-8469-4e64-a171-e33a4c557a11\",\"yes_dollars_fp\":[[\"0.0700\",\"221.00\"],[\"0.0800\",\"5000.00\"],[\"0.1000\",\"12.00\"]],\"no_dollars_fp\":[[\"0.0100\",\"106.00\"],[\"0.0200\",\"150.00\"],[\"0.0300\",\"82.00\"],[\"0.0400\",\"14.00\"],[\"0.0500\",\"20.00\"],[\"0.0600\",\"1.00\"],[\"0.0800\",\"13.00\"],[\"0.0900\",\"2.00\"],[\"0.1100\",\"10.00\"],[\"0.1200\",\"3.00\"],[\"0.1400\",\"8.00\"],[\"0.1600\",\"4.00\"],[\"0.1700\",\"6.00\"],[\"0.2000\",\"8.00\"],[\"0.2400\",\"2.00\"],[\"0.3100\",\"2.00\"],[\"0.3600\",\"2.00\"],[\"0.5500\",\"6.00\"],[\"0.8400\",\"4999.00\"]]}}\n"}
{"recv_ts_ns": 1776490453462084000, "raw": "{\"type\":\"orderbook_snapshot\",\"sid\":1,\"seq\":7,\"msg\":{\"market_ticker\":\"KXBTC-26APR1817-B77875\",\"market_id\":\"bdfea866-4146-4677-a683-1d1e460a5f07\",\"yes_dollars_fp\":[[\"0.0300\",\"5163.00\"],[\"0.0400\",\"175.00\"]],\"no_dollars_fp\":[[\"0.0100\",\"6.00\"],[\"0.0200\",\"50.00\"],[\"0.0300\",\"82.00\"],[\"0.0400\",\"143.00\"],[\"0.0500\",\"20.00\"],[\"0.0600\",\"1.00\"],[\"0.0800\",\"13.00\"],[\"0.0900\",\"2.00\"],[\"0.1100\",\"10.00\"],[\"0.1200\",\"3.00\"],[\"0.1400\",\"8.00\"],[\"0.1600\",\"4.00\"],[\"0.1700\",\"6.00\"],[\"0.2000\",\"8.00\"],[\"0.2400\",\"2.00\"],[\"0.3100\",\"2.00\"],[\"0.3600\",\"2.00\"],[\"0.7100\",\"1.00\"],[\"0.7600\",\"1.00\"],[\"0.8100\",\"1.00\"],[\"0.9000\",\"1.00\"],[\"0.9100\",\"5000.00\"]]}}\n"}
{"recv_ts_ns": 1776490453462093000, "raw": "{\"type\":\"orderbook_snapshot\",\"sid\":1,\"seq\":8,\"msg\":{\"market_ticker\":\"KXBTC-26APR1817-B78125\",\"market_id\":\"1a15bfc9-07e3-4d2c-9795-b6fa95070e1a\",\"yes_dollars_fp\":[[\"0.0100\",\"5188.00\"]],\"no_dollars_fp\":[[\"0.0100\",\"6.00\"],[\"0.0200\",\"50.00\"],[\"0.0300\",\"82.00\"],[\"0.0400\",\"69.00\"],[\"0.0500\",\"20.00\"],[\"0.0600\",\"1.00\"],[\"0.0800\",\"13.00\"],[\"0.0900\",\"2.00\"],[\"0.1100\",\"10.00\"],[\"0.1200\",\"3.00\"],[\"0.1400\",\"8.00\"],[\"0.1600\",\"4.00\"],[\"0.1700\",\"6.00\"],[\"0.2000\",\"8.00\"],[\"0.2400\",\"2.00\"],[\"0.3100\",\"2.00\"],[\"0.3600\",\"2.00\"],[\"0.7100\",\"1.00\"],[\"0.7600\",\"1.00\"],[\"0.8000\",\"250.00\"],[\"0.8100\",\"1.00\"],[\"0.8600\",\"1.00\"],[\"0.9300\",\"5000.00\"],[\"0.9400\",\"191.00\"]]}}\n"}
{"recv_ts_ns": 1776490453462102000, "raw": "{\"type\":\"subscribed\",\"id\":1,\"msg\":{\"channel\":\"trade\",\"sid\":2}}\n"}
{"recv_ts_ns": 1776490453462108000, "raw": "{\"type\":\"error\",\"id\":1,\"msg\":{\"code\":8,\"msg\":\"Unknown channel name\"}}\n"}
{"recv_ts_ns": 1776490453559202000, "raw": "{\"type\":\"error\",\"id\":1,\"msg\":{\"code\":8,\"msg\":\"Unknown channel name\"}}\n"}
{"recv_ts_ns": 1776490489853145000, "raw": "{\"type\":\"orderbook_delta\",\"sid\":1,\"seq\":9,\"msg\":{\"market_ticker\":\"KXBTC-26APR1817-B76875\",\"market_id\":\"40b92a88-8bde-4a7e-9d41-da979865ae04\",\"price_dollars\":\"0.8100\",\"delta_fp\":\"-5000.00\",\"side\":\"no\",\"ts\":\"2026-04-18T05:34:49.816683Z\"}}\n"}
{"recv_ts_ns": 1776490489891511000, "raw": "{\"type\":\"orderbook_delta\",\"sid\":1,\"seq\":10,\"msg\":{\"market_ticker\":\"KXBTC-26APR1817-B76875\",\"market_id\":\"40b92a88-8bde-4a7e-9d41-da979865ae04\",\"price_dollars\":\"0.8200\",\"delta_fp\":\"-52.00\",\"side\":\"no\",\"ts\":\"2026-04-18T05:34:49.859005Z\"}}\n"}
{"recv_ts_ns": 1776490489891567000, "raw": "{\"type\":\"orderbook_delta\",\"sid\":1,\"seq\":11,\"msg\":{\"market_ticker\":\"KXBTC-26APR1817-B76875\",\"market_id\":\"40b92a88-8bde-4a7e-9d41-da979865ae04\",\"price_dollars\":\"0.2100\",\"delta_fp\":\"64.00\",\"side\":\"no\",\"ts\":\"2026-04-18T05:34:49.860834Z\"}}\n"}
{"recv_ts_ns": 1776490489942574000, "raw": "{\"type\":\"orderbook_delta\",\"sid\":1,\"seq\":12,\"msg\":{\"market_ticker\":\"KXBTC-26APR1817-B76875\",\"market_id\":\"40b92a88-8bde-4a7e-9d41-da979865ae04\",\"price_dollars\":\"0.2100\",\"delta_fp\":\"-64.00\",\"side\":\"no\",\"ts\":\"2026-04-18T05:34:49.913951Z\"}}\n"}
{"recv_ts_ns": 1776490491901140000, "raw": "{\"type\":\"orderbook_delta\",\"sid\":1,\"seq\":13,\"msg\":{\"market_ticker\":\"KXBTC-26APR1817-B76875\",\"market_id\":\"40b92a88-8bde-4a7e-9d41-da979865ae04\",\"price_dollars\":\"0.8000\",\"delta_fp\":\"5000.00\",\"side\":\"no\",\"ts\":\"2026-04-18T05:34:51.880583Z\"}}\n"}
{"recv_ts_ns": 1776490495024424000, "raw": "{\"type\":\"orderbook_delta\",\"sid\":1,\"seq\":14,\"msg\":{\"market_ticker\":\"KXBTC-26APR1817-B77375\",\"market_id\":\"585395e9-aa6b-4085-931c-5c8399d3f5b8\",\"price_dollars\":\"0.1600\",\"delta_fp\":\"206.00\",\"side\":\"yes\",\"ts\":\"2026-04-18T05:34:54.909651Z\"}}\n"}
{"recv_ts_ns": 1776490495102704000, "raw": "{\"type\":\"orderbook_delta\",\"sid\":1,\"seq\":15,\"msg\":{\"market_ticker\":\"KXBTC-26APR1817-B76625\",\"market_id\":\"0e7966ce-51c0-40fd-a4ba-37acacc26135\",\"price_dollars\":\"0.8800\",\"delta_fp\":\"-5000.00\",\"side\":\"no\",\"ts\":\"2026-04-18T05:34:55.074608Z\"}}\n"}
{"recv_ts_ns": 1776490495123856000, "raw": "{\"type\":\"orderbook_delta\",\"sid\":1,\"seq\":16,\"msg\":{\"market_ticker\":\"KXBTC-26APR1817-B78125\",\"market_id\":\"1a15bfc9-07e3-4d2c-9795-b6fa95070e1a\",\"price_dollars\":\"0.9300\",\"delta_fp\":\"-5000.00\",\"side\":\"no\",\"ts\":\"2026-04-18T05:34:55.082248Z\"}}\n"}
{"recv_ts_ns": 1776490495143011000, "raw": "{\"type\":\"orderbook_delta\",\"sid\":1,\"seq\":17,\"msg\":{\"market_ticker\":\"KXBTC-26APR1817-B76375\",\"market_id\":\"dd3d87a3-a280-44b0-8c23-8fa091b5331e\",\"price_dollars\":\"0.0300\",\"delta_fp\":\"-5000.00\",\"side\":\"yes\",\"ts\":\"2026-04-18T05:34:55.113336Z\"}}\n"}
{"recv_ts_ns": 1776490495178827000, "raw": "{\"type\":\"orderbook_delta\",\"sid\":1,\"seq\":18,\"msg\":{\"market_ticker\":\"KXBTC-26APR1817-B78125\",\"market_id\":\"1a15bfc9-07e3-4d2c-9795-b6fa95070e1a\",\"price_dollars\":\"0.9400\",\"delta_fp\":\"-191.00\",\"side\":\"no\",\"ts\":\"2026-04-18T05:34:55.142041Z\"}}\n"}
{"recv_ts_ns": 1776490495178897000, "raw": "{\"type\":\"orderbook_delta\",\"sid\":1,\"seq\":19,\"msg\":{\"market_ticker\":\"KXBTC-26APR1817-B78125\",\"market_id\":\"1a15bfc9-07e3-4d2c-9795-b6fa95070e1a\",\"price_dollars\":\"0.0400\",\"delta_fp\":\"-55.00\",\"side\":\"no\",\"ts\":\"2026-04-18T05:34:55.144066Z\"}}\n"}
{"recv_ts_ns": 1776490495178928000, "raw": "{\"type\":\"orderbook_delta\",\"sid\":1,\"seq\":20,\"msg\":{\"market_ticker\":\"KXBTC-26APR1817-B76625\",\"market_id\":\"0e7966ce-51c0-40fd-a4ba-37acacc26135\",\"price_dollars\":\"0.8900\",\"delta_fp\":\"-210.00\",\"side\":\"no\",\"ts\":\"2026-04-18T05:34:55.144145Z\"}}\n"}
{"recv_ts_ns": 1776490495178952000, "raw": "{\"type\":\"orderbook_delta\",\"sid\":1,\"seq\":21,\"msg\":{\"market_ticker\":\"KXBTC-26APR1817-B78125\",\"market_id\":\"1a15bfc9-07e3-4d2c-9795-b6fa95070e1a\",\"price_dollars\":\"0.1000\",\"delta_fp\":\"213.00\",\"side\":\"no\",\"ts\":\"2026-04-18T05:34:55.144622Z\"}}\n"}
{"recv_ts_ns": 1776490495178973000, "raw": "{\"type\":\"orderbook_delta\",\"sid\":1,\"seq\":22,\"msg\":{\"market_ticker\":\"KXBTC-26APR1817-B76625\",\"market_id\":\"0e7966ce-51c0-40fd-a4ba-37acacc26135\",\"price_dollars\":\"0.0500\",\"delta_fp\":\"-211.00\",\"side\":\"yes\",\"ts\":\"2026-04-18T05:34:55.144705Z\"}}\n"}
{"recv_ts_ns": 1776490495178997000, "raw": "{\"type\":\"orderbook_delta\",\"sid\":1,\"seq\":23,\"msg\":{\"market_ticker\":\"KXBTC-26APR1817-B76625\",\"market_id\":\"0e7966ce-51c0-40fd-a4ba-37acacc26135\",\"price_dollars\":\"0.2100\",\"delta_fp\":\"194.00\",\"side\":\"no\",\"ts\":\"2026-04-18T05:34:55.145193Z\"}}\n"}
{"recv_ts_ns": 1776490495179018000, "raw": "{\"type\":\"orderbook_delta\",\"sid\":1,\"seq\":24,\"msg\":{\"market_ticker\":\"KXBTC-26APR1817-B76625\",\"market_id\":\"0e7966ce-51c0-40fd-a4ba-37acacc26135\",\"price_dollars\":\"0.0400\",\"delta_fp\":\"206.00\",\"side\":\"yes\",\"ts\":\"2026-04-18T05:34:55.145659Z\"}}\n"}
{"recv_ts_ns": 1776490495194677000, "raw": "{\"type\":\"orderbook_delta\",\"sid\":1,\"seq\":25,\"msg\":{\"market_ticker\":\"KXBTC-26APR1817-B76875\",\"market_id\":\"40b92a88-8bde-4a7e-9d41-da979865ae04\",\"price_dollars\":\"0.1200\",\"delta_fp\":\"-5000.00\",\"side\":\"yes\",\"ts\":\"2026-04-18T05:34:55.157874Z\"}}\n"}
{"recv_ts_ns": 1776490495194738000, "raw": "{\"type\":\"orderbook_delta\",\"sid\":1,\"seq\":26,\"msg\":{\"market_ticker\":\"KXBTC-26APR1817-B76875\",\"market_id\":\"40b92a88-8bde-4a7e-9d41-da979865ae04\",\"price_dollars\":\"0.8000\",\"delta_fp\":\"-5000.00\",\"side\":\"no\",\"ts\":\"2026-04-18T05:34:55.159303Z\"}}\n"}
{"recv_ts_ns": 1776490495203633000, "raw": "{\"type\":\"orderbook_delta\",\"sid\":1,\"seq\":27,\"msg\":{\"market_ticker\":\"KXBTC-26APR1817-B77875\",\"market_id\":\"bdfea866-4146-4677-a683-1d1e460a5f07\",\"price_dollars\":\"0.9100\",\"delta_fp\":\"-5000.00\",\"side\":\"no\",\"ts\":\"2026-04-18T05:34:55.177242Z\"}}\n"}
{"recv_ts_ns": 1776490495212722000, "raw": "{\"type\":\"orderbook_delta\",\"sid\":1,\"seq\":28,\"msg\":{\"market_ticker\":\"KXBTC-26APR1817-B76375\",\"market_id\":\"dd3d87a3-a280-44b0-8c23-8fa091b5331e\",\"price_dollars\":\"0.0300\",\"delta_fp\":\"-213.00\",\"side\":\"yes\",\"ts\":\"2026-04-18T05:34:55.192028Z\"}}\n"}
{"recv_ts_ns": 1776490495234697000, "raw": "{\"type\":\"orderbook_delta\",\"sid\":1,\"seq\":29,\"msg\":{\"market_ticker\":\"KXBTC-26APR1817-B76625\",\"market_id\":\"0e7966ce-51c0-40fd-a4ba-37acacc26135\",\"price_dollars\":\"0.2100\",\"delta_fp\":\"-194.00\",\"side\":\"no\",\"ts\":\"2026-04-18T05:34:55.208346Z\"}}\n"}
{"recv_ts_ns": 1776490495295339000, "raw": "{\"type\":\"orderbook_delta\",\"sid\":1,\"seq\":30,\"msg\":{\"market_ticker\":\"KXBTC-26APR1817-B77875\",\"market_id\":\"bdfea866-4146-4677-a683-1d1e460a5f07\",\"price_dollars\":\"0.0400\",\"delta_fp\":\"-129.00\",\"side\":\"no\",\"ts\":\"2026-04-18T05:34:55.265112Z\"}}\n"}
{"recv_ts_ns": 1776490495295380000, "raw": "{\"type\":\"orderbook_delta\",\"sid\":1,\"seq\":31,\"msg\":{\"market_ticker\":\"KXBTC-26APR1817-B77875\",\"market_id\":\"bdfea866-4146-4677-a683-1d1e460a5f07\",\"price_dollars\":\"0.0400\",\"delta_fp\":\"-175.00\",\"side\":\"yes\",\"ts\":\"2026-04-18T05:34:55.267042Z\"}}\n"}
{"recv_ts_ns": 1776490495295405000, "raw": "{\"type\":\"orderbook_delta\",\"sid\":1,\"seq\":32,\"msg\":{\"market_ticker\":\"KXBTC-26APR1817-B77875\",\"market_id\":\"bdfea866-4146-4677-a683-1d1e460a5f07\",\"price_dollars\":\"0.0300\",\"delta_fp\":\"-163.00\",\"side\":\"yes\",\"ts\":\"2026-04-18T05:34:55.267557Z\"}}\n"}
{"recv_ts_ns": 1776490495295427000, "raw": "{\"type\":\"orderbook_delta\",\"sid\":1,\"seq\":33,\"msg\":{\"market_ticker\":\"KXBTC-26APR1817-B77875\",\"market_id\":\"bdfea866-4146-4677-a683-1d1e460a5f07\",\"price_dollars\":\"0.0500\",\"delta_fp\":\"83.00\",\"side\":\"no\",\"ts\":\"2026-04-18T05:34:55.26802Z\"}}\n"}
{"recv_ts_ns": 1776490495394529000, "raw": "{\"type\":\"orderbook_delta\",\"sid\":1,\"seq\":34,\"msg\":{\"market_ticker\":\"KXBTC-26APR1817-B77875\",\"market_id\":\"bdfea866-4146-4677-a683-1d1e460a5f07\",\"price_dollars\":\"0.0500\",\"delta_fp\":\"-83.00\",\"side\":\"no\",\"ts\":\"2026-04-18T05:34:55.372896Z\"}}\n"}
{"recv_ts_ns": 1776490497082557000, "raw": "{\"type\":\"orderbook_delta\",\"sid\":1,\"seq\":35,\"msg\":{\"market_ticker\":\"KXBTC-26APR1817-B76875\",\"market_id\":\"40b92a88-8bde-4a7e-9d41-da979865ae04\",\"price_dollars\":\"0.1100\",\"delta_fp\":\"5000.00\",\"side\":\"yes\",\"ts\":\"2026-04-18T05:34:56.980841Z\"}}\n"}
{"recv_ts_ns": 1776490497082655000, "raw": "{\"type\":\"orderbook_delta\",\"sid\":1,\"seq\":36,\"msg\":{\"market_ticker\":\"KXBTC-26APR1817-B76875\",\"market_id\":\"40b92a88-8bde-4a7e-9d41-da979865ae04\",\"price_dollars\":\"0.8100\",\"delta_fp\":\"5000.00\",\"side\":\"no\",\"ts\":\"2026-04-18T05:34:56.981911Z\"}}\n"}
{"recv_ts_ns": 1776490497082686000, "raw": "{\"type\":\"orderbook_delta\",\"sid\":1,\"seq\":37,\"msg\":{\"market_ticker\":\"KXBTC-26APR1817-B76875\",\"market_id\":\"40b92a88-8bde-4a7e-9d41-da979865ae04\",\"price_dollars\":\"0.8200\",\"delta_fp\":\"67.00\",\"side\":\"no\",\"ts\":\"2026-04-18T05:34:57.039635Z\"}}\n"}
{"recv_ts_ns": 1776490497082710000, "raw": "{\"type\":\"orderbook_delta\",\"sid\":1,\"seq\":38,\"msg\":{\"market_ticker\":\"KXBTC-26APR1817-B76625\",\"market_id\":\"0e7966ce-51c0-40fd-a4ba-37acacc26135\",\"price_dollars\":\"0.8900\",\"delta_fp\":\"5000.00\",\"side\":\"no\",\"ts\":\"2026-04-18T05:34:57.049847Z\"}}\n"}
{"recv_ts_ns": 1776490497126946000, "raw": "{\"type\":\"orderbook_delta\",\"sid\":1,\"seq\":39,\"msg\":{\"market_ticker\":\"KXBTC-26APR1817-B76625\",\"market_id\":\"0e7966ce-51c0-40fd-a4ba-37acacc26135\",\"price_dollars\":\"0.0300\",\"delta_fp\":\"173.00\",\"side\":\"no\",\"ts\":\"2026-04-18T05:34:57.095279Z\"}}\n"}
{"recv_ts_ns": 1776490497127171000, "raw": "{\"type\":\"orderbook_delta\",\"sid\":1,\"seq\":40,\"msg\":{\"market_ticker\":\"KXBTC-26APR1817-B76625\",\"market_id\":\"0e7966ce-51c0-40fd-a4ba-37acacc26135\",\"price_dollars\":\"0.0500\",\"delta_fp\":\"66.00\",\"side\":\"no\",\"ts\":\"2026-04-18T05:34:57.097078Z\"}}\n"}
{"recv_ts_ns": 1776490497185125000, "raw": "{\"type\":\"orderbook_delta\",\"sid\":1,\"seq\":41,\"msg\":{\"market_ticker\":\"KXBTC-26APR1817-B78125\",\"market_id\":\"1a15bfc9-07e3-4d2c-9795-b6fa95070e1a\",\"price_dollars\":\"0.9200\",\"delta_fp\":\"5000.00\",\"side\":\"no\",\"ts\":\"2026-04-18T05:34:57.150717Z\"}}\n"}
{"recv_ts_ns": 1776490497198688000, "raw": "{\"type\":\"orderbook_delta\",\"sid\":1,\"seq\":42,\"msg\":{\"market_ticker\":\"KXBTC-26APR1817-B77875\",\"market_id\":\"bdfea866-4146-4677-a683-1d1e460a5f07\",\"price_dollars\":\"0.9000\",\"delta_fp\":\"5000.00\",\"side\":\"no\",\"ts\":\"2026-04-18T05:34:57.16015Z\"}}\n"}
{"recv_ts_ns": 1776490497240377000, "raw": "{\"type\":\"orderbook_delta\",\"sid\":1,\"seq\":43,\"msg\":{\"market_ticker\":\"KXBTC-26APR1817-B77875\",\"market_id\":\"bdfea866-4146-4677-a683-1d1e460a5f07\",\"price_dollars\":\"0.0400\",\"delta_fp\":\"187.00\",\"side\":\"yes\",\"ts\":\"2026-04-18T05:34:57.193322Z\"}}\n"}
{"recv_ts_ns": 1776490497240430000, "raw": "{\"type\":\"orderbook_delta\",\"sid\":1,\"seq\":44,\"msg\":{\"market_ticker\":\"KXBTC-26APR1817-B77875\",\"market_id\":\"bdfea866-4146-4677-a683-1d1e460a5f07\",\"price_dollars\":\"0.0400\",\"delta_fp\":\"116.00\",\"side\":\"no\",\"ts\":\"2026-04-18T05:34:57.195429Z\"}}\n"}
{"recv_ts_ns": 1776490497240458000, "raw": "{\"type\":\"orderbook_delta\",\"sid\":1,\"seq\":45,\"msg\":{\"market_ticker\":\"KXBTC-26APR1817-B77875\",\"market_id\":\"bdfea866-4146-4677-a683-1d1e460a5f07\",\"price_dollars\":\"0.0300\",\"delta_fp\":\"145.00\",\"side\":\"yes\",\"ts\":\"2026-04-18T05:34:57.197036Z\"}}\n"}
{"recv_ts_ns": 1776490497242206000, "raw": "{\"type\":\"orderbook_delta\",\"sid\":1,\"seq\":46,\"msg\":{\"market_ticker\":\"KXBTC-26APR1817-B76375\",\"market_id\":\"dd3d87a3-a280-44b0-8c23-8fa091b5331e\",\"price_dollars\":\"0.0200\",\"delta_fp\":\"5000.00\",\"side\":\"yes\",\"ts\":\"2026-04-18T05:34:57.203778Z\"}}\n"}
{"recv_ts_ns": 1776490497242236000, "raw": "{\"type\":\"orderbook_delta\",\"sid\":1,\"seq\":47,\"msg\":{\"market_ticker\":\"KXBTC-26APR1817-B78125\",\"market_id\":\"1a15bfc9-07e3-4d2c-9795-b6fa95070e1a\",\"price_dollars\":\"0.0100\",\"delta_fp\":\"-188.00\",\"side\":\"yes\",\"ts\":\"2026-04-18T05:34:57.204409Z\"}}\n"}
{"recv_ts_ns": 1776490497243943000, "raw": "{\"type\":\"orderbook_delta\",\"sid\":1,\"seq\":48,\"msg\":{\"market_ticker\":\"KXBTC-26APR1817-B78125\",\"market_id\":\"1a15bfc9-07e3-4d2c-9795-b6fa95070e1a\",\"price_dollars\":\"0.0200\",\"delta_fp\":\"197.00\",\"side\":\"yes\",\"ts\":\"2026-04-18T05:34:57.206235Z\"}}\n"}
{"recv_ts_ns": 1776490497687632000, "raw": "{\"type\":\"orderbook_delta\",\"sid\":1,\"seq\":49,\"msg\":{\"market_ticker\":\"KXBTC-26APR1817-B77375\",\"market_id\":\"585395e9-aa6b-4085-931c-5c8399d3f5b8\",\"price_dollars\":\"0.1500\",\"delta_fp\":\"-5000.00\",\"side\":\"yes\",\"ts\":\"2026-04-18T05:34:57.498523Z\"}}\n"}
{"recv_ts_ns": 1776490498185215000, "raw": "{\"type\":\"orderbook_delta\",\"sid\":1,\"seq\":50,\"msg\":{\"market_ticker\":\"KXBTC-26APR1817-B77375\",\"market_id\":\"585395e9-aa6b-4085-931c-5c8399d3f5b8\",\"price_dollars\":\"0.3600\",\"delta_fp\":\"-138.96\",\"side\":\"no\",\"ts\":\"2026-04-18T05:34:58.147436Z\"}}\n"}
{"recv_ts_ns": 1776490498203402000, "raw": "{\"type\":\"orderbook_delta\",\"sid\":1,\"seq\":51,\"msg\":{\"market_ticker\":\"KXBTC-26APR1817-B77375\",\"market_id\":\"585395e9-aa6b-4085-931c-5c8399d3f5b8\",\"price_dollars\":\"0.7800\",\"delta_fp\":\"51.88\",\"side\":\"no\",\"ts\":\"2026-04-18T05:34:58.167345Z\"}}\n"}
{"recv_ts_ns": 1776490499734376000, "raw": "{\"type\":\"orderbook_delta\",\"sid\":1,\"seq\":52,\"msg\":{\"market_ticker\":\"KXBTC-26APR1817-B77375\",\"market_id\":\"585395e9-aa6b-4085-931c-5c8399d3f5b8\",\"price_dollars\":\"0.1600\",\"delta_fp\":\"5000.00\",\"side\":\"yes\",\"ts\":\"2026-04-18T05:34:59.559907Z\"}}\n"}
{"recv_ts_ns": 1776490500223671000, "raw": "{\"type\":\"orderbook_delta\",\"sid\":1,\"seq\":53,\"msg\":{\"market_ticker\":\"KXBTC-26APR1817-B77375\",\"market_id\":\"585395e9-aa6b-4085-931c-5c8399d3f5b8\",\"price_dollars\":\"0.7800\",\"delta_fp\":\"-51.88\",\"side\":\"no\",\"ts\":\"2026-04-18T05:35:00.146254Z\"}}\n"}
{"recv_ts_ns": 1776490500223766000, "raw": "{\"type\":\"orderbook_delta\",\"sid\":1,\"seq\":54,\"msg\":{\"market_ticker\":\"KXBTC-26APR1817-B77375\",\"market_id\":\"585395e9-aa6b-4085-931c-5c8399d3f5b8\",\"price_dollars\":\"0.3600\",\"delta_fp\":\"147.16\",\"side\":\"no\",\"ts\":\"2026-04-18T05:35:00.165175Z\"}}\n"}
{"recv_ts_ns": 1776490501065478000, "raw": "{\"type\":\"orderbook_delta\",\"sid\":1,\"seq\":55,\"msg\":{\"market_ticker\":\"KXBTC-26APR1817-B76375\",\"market_id\":\"dd3d87a3-a280-44b0-8c23-8fa091b5331e\",\"price_dollars\":\"0.0200\",\"delta_fp\":\"-5000.00\",\"side\":\"yes\",\"ts\":\"2026-04-18T05:35:00.92157Z\"}}\n"}
{"recv_ts_ns": 1776490501065851000, "raw": "{\"type\":\"orderbook_delta\",\"sid\":1,\"seq\":56,\"msg\":{\"market_ticker\":\"KXBTC-26APR1817-B77375\",\"market_id\":\"585395e9-aa6b-4085-931c-5c8399d3f5b8\",\"price_dollars\":\"0.1600\",\"delta_fp\":\"-5000.00\",\"side\":\"yes\",\"ts\":\"2026-04-18T05:35:00.985075Z\"}}\n"}
{"recv_ts_ns": 1776490501065885000, "raw": "{\"type\":\"orderbook_delta\",\"sid\":1,\"seq\":57,\"msg\":{\"market_ticker\":\"KXBTC-26APR1817-B77875\",\"market_id\":\"bdfea866-4146-4677-a683-1d1e460a5f07\",\"price_dollars\":\"0.9000\",\"delta_fp\":\"-5000.00\",\"side\":\"no\",\"ts\":\"2026-04-18T05:35:01.012751Z\"}}\n"}
{"recv_ts_ns": 1776490501087526000, "raw": "{\"type\":\"orderbook_delta\",\"sid\":1,\"seq\":58,\"msg\":{\"market_ticker\":\"KXBTC-26APR1817-B77875\",\"market_id\":\"bdfea866-4146-4677-a683-1d1e460a5f07\",\"price_dollars\":\"0.0400\",\"delta_fp\":\"-116.00\",\"side\":\"no\",\"ts\":\"2026-04-18T05:35:01.064204Z\"}}\n"}
{"recv_ts_ns": 1776490501168492000, "raw": "{\"type\":\"orderbook_delta\",\"sid\":1,\"seq\":59,\"msg\":{\"market_ticker\":\"KXBTC-26APR1817-B78125\",\"market_id\":\"1a15bfc9-07e3-4d2c-9795-b6fa95070e1a\",\"price_dollars\":\"0.9200\",\"delta_fp\":\"-5000.00\",\"side\":\"no\",\"ts\":\"2026-04-18T05:35:01.138472Z\"}}\n"}
{"recv_ts_ns": 1776490502396601000, "raw": "{\"type\":\"orderbook_delta\",\"sid\":1,\"seq\":60,\"msg\":{\"market_ticker\":\"KXBTC-26APR1817-B77375\",\"market_id\":\"585395e9-aa6b-4085-931c-5c8399d3f5b8\",\"price_dollars\":\"0.3600\",\"delta_fp\":\"-147.16\",\"side\":\"no\",\"ts\":\"2026-04-18T05:35:02.146217Z\"}}\n"}
{"recv_ts_ns": 1776490502396699000, "raw": "{\"type\":\"orderbook_delta\",\"sid\":1,\"seq\":61,\"msg\":{\"market_ticker\":\"KXBTC-26APR1817-B77375\",\"market_id\":\"585395e9-aa6b-4085-931c-5c8399d3f5b8\",\"price_dollars\":\"0.7800\",\"delta_fp\":\"51.88\",\"side\":\"no\",\"ts\":\"2026-04-18T05:35:02.165968Z\"}}\n"}
{"recv_ts_ns": 1776490503011910000, "raw": "{\"type\":\"orderbook_delta\",\"sid\":1,\"seq\":62,\"msg\":{\"market_ticker\":\"KXBTC-26APR1817-B76375\",\"market_id\":\"dd3d87a3-a280-44b0-8c23-8fa091b5331e\",\"price_dollars\":\"0.0300\",\"delta_fp\":\"5000.00\",\"side\":\"yes\",\"ts\":\"2026-04-18T05:35:02.898381Z\"}}\n"}
{"recv_ts_ns": 1776490503012987000, "raw": "{\"type\":\"orderbook_delta\",\"sid\":1,\"seq\":63,\"msg\":{\"market_ticker\":\"KXBTC-26APR1817-B76375\",\"market_id\":\"dd3d87a3-a280-44b0-8c23-8fa091b5331e\",\"price_dollars\":\"0.0300\",\"delta_fp\":\"176.00\",\"side\":\"yes\",\"ts\":\"2026-04-18T05:35:02.932909Z\"}}\n"}
{"recv_ts_ns": 1776490503082472000, "raw": "{\"type\":\"orderbook_delta\",\"sid\":1,\"seq\":64,\"msg\":{\"market_ticker\":\"KXBTC-26APR1817-B77375\",\"market_id\":\"585395e9-aa6b-4085-931c-5c8399d3f5b8\",\"price_dollars\":\"0.1500\",\"delta_fp\":\"5000.00\",\"side\":\"yes\",\"ts\":\"2026-04-18T05:35:03.040749Z\"}}\n"}
{"recv_ts_ns": 1776490503130589000, "raw": "{\"type\":\"orderbook_delta\",\"sid\":1,\"seq\":65,\"msg\":{\"market_ticker\":\"KXBTC-26APR1817-B78125\",\"market_id\":\"1a15bfc9-07e3-4d2c-9795-b6fa95070e1a\",\"price_dollars\":\"0.9300\",\"delta_fp\":\"5000.00\",\"side\":\"no\",\"ts\":\"2026-04-18T05:35:03.100214Z\"}}\n"}
{"recv_ts_ns": 1776490503168274000, "raw": "{\"type\":\"orderbook_delta\",\"sid\":1,\"seq\":66,\"msg\":{\"market_ticker\":\"KXBTC-26APR1817-B77875\",\"market_id\":\"bdfea866-4146-4677-a683-1d1e460a5f07\",\"price_dollars\":\"0.9100\",\"delta_fp\":\"5000.00\",\"side\":\"no\",\"ts\":\"2026-04-18T05:35:03.137557Z\"}}\n"}
{"recv_ts_ns": 1776490503225530000, "raw": "{\"type\":\"orderbook_delta\",\"sid\":1,\"seq\":67,\"msg\":{\"market_ticker\":\"KXBTC-26APR1817-B77875\",\"market_id\":\"bdfea866-4146-4677-a683-1d1e460a5f07\",\"price_dollars\":\"0.0400\",\"delta_fp\":\"112.00\",\"side\":\"no\",\"ts\":\"2026-04-18T05:35:03.194655Z\"}}\n"}
{"recv_ts_ns": 1776490503727409000, "raw": "{\"type\":\"orderbook_delta\",\"sid\":1,\"seq\":68,\"msg\":{\"market_ticker\":\"KXBTC-26APR1817-B77375\",\"market_id\":\"585395e9-aa6b-4085-931c-5c8399d3f5b8\",\"price_dollars\":\"0.7800\",\"delta_fp\":\"-51.88\",\"side\":\"no\",\"ts\":\"2026-04-18T05:35:03.644609Z\"}}\n"}
{"recv_ts_ns": 1776490506286454000, "raw": "{\"type\":\"orderbook_delta\",\"sid\":1,\"seq\":69,\"msg\":{\"market_ticker\":\"KXBTC-26APR1817-B77375\",\"market_id\":\"585395e9-aa6b-4085-931c-5c8399d3f5b8\",\"price_dollars\":\"0.3600\",\"delta_fp\":\"145.90\",\"side\":\"no\",\"ts\":\"2026-04-18T05:35:06.146028Z\"}}\n"}
{"recv_ts_ns": 1776490513468438000, "raw": "{\"type\":\"error\",\"id\":99,\"msg\":{\"code\":8,\"msg\":\"Unknown channel name\"}}\n"}
